<?xml version="1.0" ?>
<robot xmlns:xacro="http://ros.org/wiki/xacro">

  <!-- left leg -->
  <xacro:macro name="alfarobi_l_leg" params="parent">

  <!-- left hip yaw joint -->
  <joint name="l_hip_yaw" type="revolute">
    <parent link="${parent}"/>
    <child link="l_hip_yaw_link"/>
    <origin xyz="0.0175 0.0384 -0.09728" rpy="0 0 0" />
    <axis xyz="0 0 -1" />
    <limit effort="2.8" velocity="5.6548668" lower="-2.6179939" upper="2.6179939" />
  </joint>
  <xacro:insert_transmission name="l_hip_yaw" />

<!-- left hip yaw link -->
<link name="l_hip_yaw_link">
  <visual>
    <xacro:insert_mesh_l_hip_yaw_link />
  </visual>
  <collision>
    <geometry>
      <mesh filename="package://alfarobi_description/mesh/hip_yaw.stl"  scale="1 1 1"/>
    </geometry>
  </collision>
  <inertial>
    <xacro:insert_inertia_l_hip_yaw_link />
  </inertial>
</link>

  <!-- left hip roll joint -->
  <joint name="l_hip_roll" type="revolute">
    <parent link="l_hip_yaw_link"/>
    <child link="l_hip_roll_link"/>
    <origin xyz="-0.003 0 -0.0335" rpy="0 0 0" />
    <axis xyz="-1 0 0" />
    <limit effort="2.8" velocity="5.6548668" lower="-2.6179939" upper="2.6179939" />
  </joint>
  <xacro:insert_transmission name="l_hip_roll" />

<!-- left hip roll link -->
<link name="l_hip_roll_link">
  <visual>
    <xacro:insert_mesh_l_hip_roll_link />
  </visual>
  <collision>
    <geometry>
      <mesh filename="package://alfarobi_description/mesh/l_hip_roll.stl"  scale="1 1 1"/>
    </geometry>
  </collision>
  <inertial>
    <xacro:insert_inertia_l_hip_roll_link />
  </inertial>
</link>

  <!-- left hip pitch joint -->
  <joint name="l_hip_pitch" type="revolute">
    <parent link="l_hip_roll_link"/>
    <child link="l_hip_pitch_link"/>
    <origin xyz="0 0 0" rpy="0 0 0" />
    <axis xyz="0 -1 0" />
    <limit effort="2.8" velocity="5.6548668" lower="-2.6179939" upper="2.6179939" />
  </joint>
  <xacro:insert_transmission name="l_hip_pitch" />

<!-- left hip pitch link -->
<link name="l_hip_pitch_link">
  <visual>
    <xacro:insert_mesh_l_hip_pitch_link />
  </visual>
  <collision>
    <geometry>
       <mesh filename="package://alfarobi_description/mesh/l_hip_pitch.stl"  scale="1 1 1"/>
    </geometry>
  </collision>
  <inertial>
    <xacro:insert_inertia_l_hip_pitch_link />
  </inertial>
</link>

  <!-- left knee joint -->
  <joint name="l_knee" type="revolute">
    <parent link="l_hip_pitch_link"/>
    <child link="l_knee_link"/>
    <origin xyz="0 0 -0.1168" rpy="0 0 0" />
    <axis xyz="0 -1 0" />
    <limit effort="2.8" velocity="5.6548668" lower="-2.6179939" upper="2.6179939" />
  </joint>
  <xacro:insert_transmission name="l_knee" />

<!-- left knee link -->
<link name="l_knee_link">
  <visual>
    <xacro:insert_mesh_l_knee_link />
  </visual>
  <collision>
    <geometry>
      <mesh filename="package://alfarobi_description/mesh/lower_leg.stl"  scale="1 1 1"/>
    </geometry>
  </collision>
  <inertial>
    <xacro:insert_inertia_l_knee_link />
  </inertial>
</link>

  <!-- left ankle pitch link -->
  <joint name="l_ank_pitch" type="revolute">
    <parent link="l_knee_link"/>
    <child link="l_ank_pitch_link"/>
    <origin xyz="0 0 -0.1168" rpy="0 0 0" />
    <axis xyz="0 1 0" />
    <limit effort="2.8" velocity="5.6548668" lower="-2.6179939" upper="2.6179939" />
  </joint>
  <xacro:insert_transmission name="l_ank_pitch" />

<!-- left ankle pitch link -->
<link name="l_ank_pitch_link">
  <visual>
    <xacro:insert_mesh_l_ank_pitch_link />
  </visual>
  <collision>
    <geometry>
      <mesh filename="package://alfarobi_description/mesh/l_ank_pitch.stl"  scale="1 1 1"/>
    </geometry>
  </collision>
  <inertial>
    <xacro:insert_inertia_l_ank_pitch_link />
  </inertial>
</link>

  <!-- left ankle roll link -->
  <joint name="l_ank_roll" type="revolute">
    <parent link="l_ank_pitch_link"/>
    <child link="l_ank_roll_link"/>
    <origin xyz="0 0 0" rpy="0 0 0" />
    <axis xyz="1 0 0" />
    <limit effort="2.8" velocity="5.6548668" lower="-2.6179939" upper="2.6179939" />
  </joint>
  <xacro:insert_transmission name="l_ank_roll" />

<!-- left ankle roll link -->
<link name="l_ank_roll_link">
  <visual>
    <xacro:insert_mesh_l_ank_roll_link />
  </visual>
  <collision>
    <geometry>
      <mesh filename="package://alfarobi_description/mesh/l_ank_roll.stl"  scale="1 1 1"/>
    </geometry>
  </collision>
  <inertial>
    <xacro:insert_inertia_l_ank_roll_link />
  </inertial>
</link>

  </xacro:macro>

</robot>
